"""
Integration test for DataForSEO API error handling.

This test validates comprehensive error handling for DataForSEO API failures.
The test must FAIL before implementation and PASS after implementation.
"""

import pytest
from fastapi.testclient import TestClient
from unittest.mock import patch, MagicMock, AsyncMock
import json
import asyncio


class TestDataForSEOErrors:
    """Integration test suite for DataForSEO API error handling."""
    
    def setup_method(self):
        """Set up test client and mock data."""
        # This will be updated when the actual FastAPI app is created
        self.client = None  # Will be replaced with actual TestClient
    
    @pytest.mark.asyncio
    async def test_rate_limit_error_handling(self):
        """Test handling of DataForSEO rate limit errors."""
        with patch('backend.src.dataforseo.api_client.DataForSEOClient') as mock_client_class:
            mock_client = AsyncMock()
            mock_client_class.return_value = mock_client
            
            # Mock rate limit error
            mock_client.get_trends_data.side_effect = Exception("Rate limit exceeded")
            
            with patch('backend.src.dataforseo.api_client.get_api_credentials') as mock_creds:
                mock_creds.return_value = {
                    "base_url": "https://api.dataforseo.com",
                    "key_value": "test_api_key"
                }
                
                # Test trend analysis rate limit
                response = self.client.get(
                    "/api/v1/trend-analysis/dataforseo",
                    params={
                        "subtopics": "weight loss",
                        "location": "United States"
                    }
                )
                
                assert response.status_code == 429
                data = response.json()
                assert data["success"] is False
                assert data["error"] == "RATE_LIMIT_EXCEEDED"
                assert "retry_after" in data.get("details", {})
                
                # Test keyword research rate limit
                response = self.client.post(
                    "/api/v1/keyword-research/dataforseo",
                    json={
                        "seed_keywords": ["weight loss tips"],
                        "max_difficulty": 50
                    }
                )
                
                assert response.status_code == 429
                data = response.json()
                assert data["success"] is False
                assert data["error"] == "RATE_LIMIT_EXCEEDED"
    
    @pytest.mark.asyncio
    async def test_quota_exceeded_error_handling(self):
        """Test handling of DataForSEO quota exceeded errors."""
        with patch('backend.src.dataforseo.api_client.DataForSEOClient') as mock_client_class:
            mock_client = AsyncMock()
            mock_client_class.return_value = mock_client
            
            # Mock quota exceeded error
            mock_client.get_trends_data.side_effect = Exception("Quota exceeded")
            
            with patch('backend.src.dataforseo.api_client.get_api_credentials') as mock_creds:
                mock_creds.return_value = {
                    "base_url": "https://api.dataforseo.com",
                    "key_value": "test_api_key"
                }
                
                response = self.client.get(
                    "/api/v1/trend-analysis/dataforseo",
                    params={
                        "subtopics": "weight loss",
                        "location": "United States"
                    }
                )
                
                assert response.status_code == 429
                data = response.json()
                assert data["success"] is False
                assert data["error"] == "RATE_LIMIT_EXCEEDED"
                assert "quota_remaining" in data.get("details", {})
    
    @pytest.mark.asyncio
    async def test_api_unavailable_error_handling(self):
        """Test handling of DataForSEO API unavailable errors."""
        with patch('backend.src.dataforseo.api_client.DataForSEOClient') as mock_client_class:
            mock_client = AsyncMock()
            mock_client_class.return_value = mock_client
            
            # Mock API unavailable error
            mock_client.get_trends_data.side_effect = Exception("API unavailable")
            
            with patch('backend.src.dataforseo.api_client.get_api_credentials') as mock_creds:
                mock_creds.return_value = {
                    "base_url": "https://api.dataforseo.com",
                    "key_value": "test_api_key"
                }
                
                response = self.client.get(
                    "/api/v1/trend-analysis/dataforseo",
                    params={
                        "subtopics": "weight loss",
                        "location": "United States"
                    }
                )
                
                assert response.status_code == 500
                data = response.json()
                assert data["success"] is False
                assert data["error"] == "API_UNAVAILABLE"
                assert "retry_after" in data.get("details", {})
    
    @pytest.mark.asyncio
    async def test_invalid_api_key_error_handling(self):
        """Test handling of invalid API key errors."""
        with patch('backend.src.dataforseo.api_client.DataForSEOClient') as mock_client_class:
            mock_client = AsyncMock()
            mock_client_class.return_value = mock_client
            
            # Mock invalid API key error
            mock_client.get_trends_data.side_effect = Exception("Invalid API key")
            
            with patch('backend.src.dataforseo.api_client.get_api_credentials') as mock_creds:
                mock_creds.return_value = {
                    "base_url": "https://api.dataforseo.com",
                    "key_value": "invalid_key"
                }
                
                response = self.client.get(
                    "/api/v1/trend-analysis/dataforseo",
                    params={
                        "subtopics": "weight loss",
                        "location": "United States"
                    }
                )
                
                assert response.status_code == 401
                data = response.json()
                assert data["success"] is False
                assert data["error"] == "INVALID_API_KEY"
    
    @pytest.mark.asyncio
    async def test_network_timeout_error_handling(self):
        """Test handling of network timeout errors."""
        with patch('backend.src.dataforseo.api_client.DataForSEOClient') as mock_client_class:
            mock_client = AsyncMock()
            mock_client_class.return_value = mock_client
            
            # Mock network timeout error
            mock_client.get_trends_data.side_effect = asyncio.TimeoutError("Request timeout")
            
            with patch('backend.src.dataforseo.api_client.get_api_credentials') as mock_creds:
                mock_creds.return_value = {
                    "base_url": "https://api.dataforseo.com",
                    "key_value": "test_api_key"
                }
                
                response = self.client.get(
                    "/api/v1/trend-analysis/dataforseo",
                    params={
                        "subtopics": "weight loss",
                        "location": "United States"
                    }
                )
                
                assert response.status_code == 408
                data = response.json()
                assert data["success"] is False
                assert data["error"] == "REQUEST_TIMEOUT"
    
    @pytest.mark.asyncio
    async def test_invalid_response_format_error_handling(self):
        """Test handling of invalid response format errors."""
        with patch('backend.src.dataforseo.api_client.DataForSEOClient') as mock_client_class:
            mock_client = AsyncMock()
            mock_client_class.return_value = mock_client
            
            # Mock invalid response format
            mock_client.get_trends_data.return_value = {"invalid": "format"}
            
            with patch('backend.src.dataforseo.api_client.get_api_credentials') as mock_creds:
                mock_creds.return_value = {
                    "base_url": "https://api.dataforseo.com",
                    "key_value": "test_api_key"
                }
                
                response = self.client.get(
                    "/api/v1/trend-analysis/dataforseo",
                    params={
                        "subtopics": "weight loss",
                        "location": "United States"
                    }
                )
                
                assert response.status_code == 500
                data = response.json()
                assert data["success"] is False
                assert data["error"] == "INVALID_RESPONSE_FORMAT"
    
    @pytest.mark.asyncio
    async def test_exponential_backoff_retry_logic(self):
        """Test exponential backoff retry logic for transient errors."""
        with patch('backend.src.dataforseo.api_client.DataForSEOClient') as mock_client_class:
            mock_client = AsyncMock()
            mock_client_class.return_value = mock_client
            
            # Mock transient error followed by success
            call_count = 0
            def mock_get_trends_data(*args, **kwargs):
                nonlocal call_count
                call_count += 1
                if call_count <= 2:
                    raise Exception("Temporary error")
                return {
                    "tasks": [
                        {
                            "result": [
                                {
                                    "keyword": "weight loss",
                                    "location": "United States",
                                    "time_series": [{"date": "2024-01-01", "value": 75}]
                                }
                            ]
                        }
                    ]
                }
            
            mock_client.get_trends_data.side_effect = mock_get_trends_data
            
            with patch('backend.src.dataforseo.api_client.get_api_credentials') as mock_creds:
                mock_creds.return_value = {
                    "base_url": "https://api.dataforseo.com",
                    "key_value": "test_api_key"
                }
                
                # Mock exponential backoff
                with patch('asyncio.sleep') as mock_sleep:
                    response = self.client.get(
                        "/api/v1/trend-analysis/dataforseo",
                        params={
                            "subtopics": "weight loss",
                            "location": "United States"
                        }
                    )
                    
                    assert response.status_code == 200
                    data = response.json()
                    assert data["success"] is True
                    
                    # Verify retry attempts
                    assert call_count == 3
                    # Verify exponential backoff was used
                    assert mock_sleep.call_count == 2
    
    @pytest.mark.asyncio
    async def test_circuit_breaker_pattern(self):
        """Test circuit breaker pattern for repeated failures."""
        with patch('backend.src.dataforseo.api_client.DataForSEOClient') as mock_client_class:
            mock_client = AsyncMock()
            mock_client_class.return_value = mock_client
            
            # Mock repeated failures
            mock_client.get_trends_data.side_effect = Exception("Persistent error")
            
            with patch('backend.src.dataforseo.api_client.get_api_credentials') as mock_creds:
                mock_creds.return_value = {
                    "base_url": "https://api.dataforseo.com",
                    "key_value": "test_api_key"
                }
                
                # Mock circuit breaker
                with patch('backend.src.dataforseo.error_service.CircuitBreaker') as mock_circuit_breaker:
                    mock_circuit_breaker.return_value.is_open.return_value = True
                    
                    response = self.client.get(
                        "/api/v1/trend-analysis/dataforseo",
                        params={
                            "subtopics": "weight loss",
                            "location": "United States"
                        }
                    )
                    
                    assert response.status_code == 503
                    data = response.json()
                    assert data["success"] is False
                    assert data["error"] == "CIRCUIT_BREAKER_OPEN"
    
    @pytest.mark.asyncio
    async def test_fallback_to_cached_data(self):
        """Test fallback to cached data when API fails."""
        with patch('backend.src.dataforseo.cache_service.RedisCache') as mock_redis:
            mock_redis_instance = AsyncMock()
            mock_redis.return_value = mock_redis_instance
            
            # Mock cached data
            cached_data = {
                "success": True,
                "data": [
                    {
                        "keyword": "weight loss",
                        "location": "United States",
                        "time_series": [{"date": "2024-01-01", "value": 75}],
                        "created_at": "2025-01-14T10:00:00Z",
                        "updated_at": "2025-01-14T10:00:00Z"
                    }
                ],
                "metadata": {
                    "cache_status": "cached"
                }
            }
            mock_redis_instance.get.return_value = json.dumps(cached_data)
            
            with patch('backend.src.dataforseo.api_client.DataForSEOClient') as mock_client_class:
                mock_client = AsyncMock()
                mock_client_class.return_value = mock_client
                mock_client.get_trends_data.side_effect = Exception("API unavailable")
                
                with patch('backend.src.dataforseo.api_client.get_api_credentials') as mock_creds:
                    mock_creds.return_value = {
                        "base_url": "https://api.dataforseo.com",
                        "key_value": "test_api_key"
                    }
                    
                    response = self.client.get(
                        "/api/v1/trend-analysis/dataforseo",
                        params={
                            "subtopics": "weight loss",
                            "location": "United States"
                        }
                    )
                    
                    assert response.status_code == 200
                    data = response.json()
                    assert data["success"] is True
                    assert data["metadata"]["cache_status"] == "cached"
    
    @pytest.mark.asyncio
    async def test_error_logging_and_monitoring(self):
        """Test error logging and monitoring."""
        with patch('backend.src.dataforseo.api_client.DataForSEOClient') as mock_client_class:
            mock_client = AsyncMock()
            mock_client_class.return_value = mock_client
            mock_client.get_trends_data.side_effect = Exception("Test error")
            
            with patch('backend.src.dataforseo.api_client.get_api_credentials') as mock_creds:
                mock_creds.return_value = {
                    "base_url": "https://api.dataforseo.com",
                    "key_value": "test_api_key"
                }
                
                # Mock logger
                with patch('backend.src.dataforseo.error_service.logger') as mock_logger:
                    response = self.client.get(
                        "/api/v1/trend-analysis/dataforseo",
                        params={
                            "subtopics": "weight loss",
                            "location": "United States"
                        }
                    )
                    
                    assert response.status_code == 500
                    
                    # Verify error was logged
                    mock_logger.error.assert_called()
                    error_call = mock_logger.error.call_args[0][0]
                    assert "DataForSEO API error" in error_call
                    assert "Test error" in error_call
